2023-03-29 21:24:37,777 ERROR Internal Server Error: /news/ C:\Users\Dmitr\PycharmProjects\project_dir\Lena\lib\site-packages\django\utils\log.py (<class 'django.template.exceptions.TemplateSyntaxError'>, TemplateSyntaxError("Invalid filter: 'truncate1chars'"), <traceback object at 0x000001C6016D4340>)
Traceback (most recent call last):
  File "C:\Users\Dmitr\PycharmProjects\project_dir\Lena\lib\site-packages\django\core\handlers\exception.py", line 55, in inner
    response = get_response(request)
  File "C:\Users\Dmitr\PycharmProjects\project_dir\Lena\lib\site-packages\django\core\handlers\base.py", line 220, in _get_response
    response = response.render()
  File "C:\Users\Dmitr\PycharmProjects\project_dir\Lena\lib\site-packages\django\template\response.py", line 114, in render
    self.content = self.rendered_content
  File "C:\Users\Dmitr\PycharmProjects\project_dir\Lena\lib\site-packages\django\template\response.py", line 90, in rendered_content
    template = self.resolve_template(self.template_name)
  File "C:\Users\Dmitr\PycharmProjects\project_dir\Lena\lib\site-packages\django\template\response.py", line 72, in resolve_template
    return select_template(template, using=self.using)
  File "C:\Users\Dmitr\PycharmProjects\project_dir\Lena\lib\site-packages\django\template\loader.py", line 42, in select_template
    return engine.get_template(template_name)
  File "C:\Users\Dmitr\PycharmProjects\project_dir\Lena\lib\site-packages\django\template\backends\django.py", line 34, in get_template
    return Template(self.engine.get_template(template_name), self)
  File "C:\Users\Dmitr\PycharmProjects\project_dir\Lena\lib\site-packages\django\template\engine.py", line 175, in get_template
    template, origin = self.find_template(template_name)
  File "C:\Users\Dmitr\PycharmProjects\project_dir\Lena\lib\site-packages\django\template\engine.py", line 157, in find_template
    template = loader.get_template(name, skip=skip)
  File "C:\Users\Dmitr\PycharmProjects\project_dir\Lena\lib\site-packages\django\template\loaders\cached.py", line 57, in get_template
    template = super().get_template(template_name, skip)
  File "C:\Users\Dmitr\PycharmProjects\project_dir\Lena\lib\site-packages\django\template\loaders\base.py", line 28, in get_template
    return Template(
  File "C:\Users\Dmitr\PycharmProjects\project_dir\Lena\lib\site-packages\django\template\base.py", line 154, in __init__
    self.nodelist = self.compile_nodelist()
  File "C:\Users\Dmitr\PycharmProjects\project_dir\Lena\lib\site-packages\django\template\base.py", line 200, in compile_nodelist
    return parser.parse()
  File "C:\Users\Dmitr\PycharmProjects\project_dir\Lena\lib\site-packages\django\template\base.py", line 513, in parse
    raise self.error(token, e)
  File "C:\Users\Dmitr\PycharmProjects\project_dir\Lena\lib\site-packages\django\template\base.py", line 511, in parse
    compiled_result = compile_func(self, token)
  File "C:\Users\Dmitr\PycharmProjects\project_dir\Lena\lib\site-packages\django\template\loader_tags.py", line 293, in do_extends
    nodelist = parser.parse()
  File "C:\Users\Dmitr\PycharmProjects\project_dir\Lena\lib\site-packages\django\template\base.py", line 513, in parse
    raise self.error(token, e)
  File "C:\Users\Dmitr\PycharmProjects\project_dir\Lena\lib\site-packages\django\template\base.py", line 511, in parse
    compiled_result = compile_func(self, token)
  File "C:\Users\Dmitr\PycharmProjects\project_dir\Lena\lib\site-packages\django\template\loader_tags.py", line 232, in do_block
    nodelist = parser.parse(("endblock",))
  File "C:\Users\Dmitr\PycharmProjects\project_dir\Lena\lib\site-packages\django\template\base.py", line 513, in parse
    raise self.error(token, e)
  File "C:\Users\Dmitr\PycharmProjects\project_dir\Lena\lib\site-packages\django\template\base.py", line 511, in parse
    compiled_result = compile_func(self, token)
  File "C:\Users\Dmitr\PycharmProjects\project_dir\Lena\lib\site-packages\django\template\defaulttags.py", line 558, in autoescape
    nodelist = parser.parse(("endautoescape",))
  File "C:\Users\Dmitr\PycharmProjects\project_dir\Lena\lib\site-packages\django\template\base.py", line 513, in parse
    raise self.error(token, e)
  File "C:\Users\Dmitr\PycharmProjects\project_dir\Lena\lib\site-packages\django\template\base.py", line 511, in parse
    compiled_result = compile_func(self, token)
  File "C:\Users\Dmitr\PycharmProjects\project_dir\Lena\lib\site-packages\django\template\defaulttags.py", line 954, in do_if
    nodelist = parser.parse(("elif", "else", "endif"))
  File "C:\Users\Dmitr\PycharmProjects\project_dir\Lena\lib\site-packages\django\template\base.py", line 513, in parse
    raise self.error(token, e)
  File "C:\Users\Dmitr\PycharmProjects\project_dir\Lena\lib\site-packages\django\template\base.py", line 511, in parse
    compiled_result = compile_func(self, token)
  File "C:\Users\Dmitr\PycharmProjects\project_dir\Lena\lib\site-packages\django\template\defaulttags.py", line 854, in do_for
    nodelist_loop = parser.parse(
  File "C:\Users\Dmitr\PycharmProjects\project_dir\Lena\lib\site-packages\django\template\base.py", line 484, in parse
    raise self.error(token, e)
  File "C:\Users\Dmitr\PycharmProjects\project_dir\Lena\lib\site-packages\django\template\base.py", line 482, in parse
    filter_expression = self.compile_filter(token.contents)
  File "C:\Users\Dmitr\PycharmProjects\project_dir\Lena\lib\site-packages\django\template\base.py", line 600, in compile_filter
    return FilterExpression(token, self)
  File "C:\Users\Dmitr\PycharmProjects\project_dir\Lena\lib\site-packages\django\template\base.py", line 698, in __init__
    filter_func = parser.find_filter(filter_name)
  File "C:\Users\Dmitr\PycharmProjects\project_dir\Lena\lib\site-packages\django\template\base.py", line 606, in find_filter
    raise TemplateSyntaxError("Invalid filter: '%s'" % filter_name)
django.template.exceptions.TemplateSyntaxError: Invalid filter: 'truncate1chars'
2023-03-29 21:24:37,793 ERROR "GET /news/?page=4 HTTP/1.1" 500 347870 C:\Users\Dmitr\PycharmProjects\project_dir\Lena\lib\site-packages\django\core\servers\basehttp.py None
2023-03-29 21:43:28,261 ERROR Internal Server Error: /news/articles/45/edit/ C:\Users\Dmitr\PycharmProjects\project_dir\Lena\lib\site-packages\django\utils\log.py (<class 'kombu.exceptions.OperationalError'>, OperationalError("Error while reading from redis-14545.c266.us-east-1-3.ec2.cloud.redislabs.com:14545 : (10054, 'Удаленный хост принудительно разорвал существующее подключение', None, 10054, None)"), <traceback object at 0x000001B38D831500>)
Traceback (most recent call last):
  File "C:\Users\Dmitr\PycharmProjects\project_dir\Lena\lib\site-packages\kombu\utils\functional.py", line 30, in __call__
    return self.__value__
AttributeError: 'ChannelPromise' object has no attribute '__value__'

During handling of the above exception, another exception occurred:

Traceback (most recent call last):
  File "C:\Users\Dmitr\PycharmProjects\project_dir\Lena\lib\site-packages\kombu\transport\virtual\base.py", line 925, in create_channel
    return self._avail_channels.pop()
IndexError: pop from empty list

During handling of the above exception, another exception occurred:

Traceback (most recent call last):
  File "C:\Users\Dmitr\PycharmProjects\project_dir\Lena\lib\site-packages\redis\connection.py", line 940, in read_response
    response = self._parser.read_response(disable_decoding=disable_decoding)
  File "C:\Users\Dmitr\PycharmProjects\project_dir\Lena\lib\site-packages\redis\connection.py", line 345, in read_response
    result = self._read_response(disable_decoding=disable_decoding)
  File "C:\Users\Dmitr\PycharmProjects\project_dir\Lena\lib\site-packages\redis\connection.py", line 355, in _read_response
    raw = self._buffer.readline()
  File "C:\Users\Dmitr\PycharmProjects\project_dir\Lena\lib\site-packages\redis\connection.py", line 258, in readline
    self._read_from_socket()
  File "C:\Users\Dmitr\PycharmProjects\project_dir\Lena\lib\site-packages\redis\connection.py", line 208, in _read_from_socket
    data = self._sock.recv(socket_read_size)
ConnectionResetError: [WinError 10054] Удаленный хост принудительно разорвал существующее подключение

During handling of the above exception, another exception occurred:

Traceback (most recent call last):
  File "C:\Users\Dmitr\PycharmProjects\project_dir\Lena\lib\site-packages\kombu\connection.py", line 446, in _reraise_as_library_errors
    yield
  File "C:\Users\Dmitr\PycharmProjects\project_dir\Lena\lib\site-packages\kombu\connection.py", line 433, in _ensure_connection
    return retry_over_time(
  File "C:\Users\Dmitr\PycharmProjects\project_dir\Lena\lib\site-packages\kombu\utils\functional.py", line 312, in retry_over_time
    return fun(*args, **kwargs)
  File "C:\Users\Dmitr\PycharmProjects\project_dir\Lena\lib\site-packages\kombu\connection.py", line 877, in _connection_factory
    self._connection = self._establish_connection()
  File "C:\Users\Dmitr\PycharmProjects\project_dir\Lena\lib\site-packages\kombu\connection.py", line 812, in _establish_connection
    conn = self.transport.establish_connection()
  File "C:\Users\Dmitr\PycharmProjects\project_dir\Lena\lib\site-packages\kombu\transport\virtual\base.py", line 949, in establish_connection
    self._avail_channels.append(self.create_channel(self))
  File "C:\Users\Dmitr\PycharmProjects\project_dir\Lena\lib\site-packages\kombu\transport\virtual\base.py", line 927, in create_channel
    channel = self.Channel(connection)
  File "C:\Users\Dmitr\PycharmProjects\project_dir\Lena\lib\site-packages\kombu\transport\redis.py", line 737, in __init__
    self.client.ping()
  File "C:\Users\Dmitr\PycharmProjects\project_dir\Lena\lib\site-packages\redis\commands\core.py", line 1194, in ping
    return self.execute_command("PING", **kwargs)
  File "C:\Users\Dmitr\PycharmProjects\project_dir\Lena\lib\site-packages\redis\client.py", line 1258, in execute_command
    return conn.retry.call_with_retry(
  File "C:\Users\Dmitr\PycharmProjects\project_dir\Lena\lib\site-packages\redis\retry.py", line 49, in call_with_retry
    fail(error)
  File "C:\Users\Dmitr\PycharmProjects\project_dir\Lena\lib\site-packages\redis\client.py", line 1262, in <lambda>
    lambda error: self._disconnect_raise(conn, error),
  File "C:\Users\Dmitr\PycharmProjects\project_dir\Lena\lib\site-packages\redis\client.py", line 1248, in _disconnect_raise
    raise error
  File "C:\Users\Dmitr\PycharmProjects\project_dir\Lena\lib\site-packages\redis\retry.py", line 46, in call_with_retry
    return do()
  File "C:\Users\Dmitr\PycharmProjects\project_dir\Lena\lib\site-packages\redis\client.py", line 1259, in <lambda>
    lambda: self._send_command_parse_response(
  File "C:\Users\Dmitr\PycharmProjects\project_dir\Lena\lib\site-packages\redis\client.py", line 1235, in _send_command_parse_response
    return self.parse_response(conn, command_name, **options)
  File "C:\Users\Dmitr\PycharmProjects\project_dir\Lena\lib\site-packages\redis\client.py", line 1275, in parse_response
    response = connection.read_response()
  File "C:\Users\Dmitr\PycharmProjects\project_dir\Lena\lib\site-packages\redis\connection.py", line 946, in read_response
    raise ConnectionError(
redis.exceptions.ConnectionError: Error while reading from redis-14545.c266.us-east-1-3.ec2.cloud.redislabs.com:14545 : (10054, 'Удаленный хост принудительно разорвал существующее подключение', None, 10054, None)

The above exception was the direct cause of the following exception:

Traceback (most recent call last):
  File "C:\Users\Dmitr\PycharmProjects\project_dir\Lena\lib\site-packages\django\core\handlers\exception.py", line 55, in inner
    response = get_response(request)
  File "C:\Users\Dmitr\PycharmProjects\project_dir\Lena\lib\site-packages\django\core\handlers\base.py", line 197, in _get_response
    response = wrapped_callback(request, *callback_args, **callback_kwargs)
  File "C:\Users\Dmitr\PycharmProjects\project_dir\Lena\lib\site-packages\django\views\generic\base.py", line 103, in view
    return self.dispatch(request, *args, **kwargs)
  File "C:\Users\Dmitr\PycharmProjects\project_dir\Lena\lib\site-packages\django\contrib\auth\mixins.py", line 109, in dispatch
    return super().dispatch(request, *args, **kwargs)
  File "C:\Users\Dmitr\PycharmProjects\project_dir\Lena\lib\site-packages\django\views\generic\base.py", line 142, in dispatch
    return handler(request, *args, **kwargs)
  File "C:\Users\Dmitr\PycharmProjects\project_dir\Lena\lib\site-packages\django\views\generic\edit.py", line 208, in post
    return super().post(request, *args, **kwargs)
  File "C:\Users\Dmitr\PycharmProjects\project_dir\Lena\lib\site-packages\django\views\generic\edit.py", line 153, in post
    return self.form_valid(form)
  File "C:\Users\Dmitr\PycharmProjects\project_dir\NewsPaper\News\views.py", line 98, in form_valid
    return super().form_valid(form)
  File "C:\Users\Dmitr\PycharmProjects\project_dir\Lena\lib\site-packages\django\views\generic\edit.py", line 135, in form_valid
    self.object = form.save()
  File "C:\Users\Dmitr\PycharmProjects\project_dir\Lena\lib\site-packages\django\forms\models.py", line 549, in save
    self._save_m2m()
  File "C:\Users\Dmitr\PycharmProjects\project_dir\Lena\lib\site-packages\django\forms\models.py", line 530, in _save_m2m
    f.save_form_data(self.instance, cleaned_data[f.name])
  File "C:\Users\Dmitr\PycharmProjects\project_dir\Lena\lib\site-packages\django\db\models\fields\related.py", line 1966, in save_form_data
    getattr(instance, self.attname).set(data)
  File "C:\Users\Dmitr\PycharmProjects\project_dir\Lena\lib\site-packages\django\db\models\fields\related_descriptors.py", line 1169, in set
    self.add(*new_objs, through_defaults=through_defaults)
  File "C:\Users\Dmitr\PycharmProjects\project_dir\Lena\lib\site-packages\django\db\models\fields\related_descriptors.py", line 1087, in add
    self._add_items(
  File "C:\Users\Dmitr\PycharmProjects\project_dir\Lena\lib\site-packages\django\db\models\fields\related_descriptors.py", line 1373, in _add_items
    signals.m2m_changed.send(
  File "C:\Users\Dmitr\PycharmProjects\project_dir\Lena\lib\site-packages\django\dispatch\dispatcher.py", line 176, in send
    return [
  File "C:\Users\Dmitr\PycharmProjects\project_dir\Lena\lib\site-packages\django\dispatch\dispatcher.py", line 177, in <listcomp>
    (receiver, receiver(signal=self, sender=sender, **named))
  File "C:\Users\Dmitr\PycharmProjects\project_dir\NewsPaper\News\signals.py", line 14, in notif_subs
    post_created.apply_async((instance.id, instance.title, instance.text),
  File "C:\Users\Dmitr\PycharmProjects\project_dir\Lena\lib\site-packages\celery\app\task.py", line 575, in apply_async
    return app.send_task(
  File "C:\Users\Dmitr\PycharmProjects\project_dir\Lena\lib\site-packages\celery\app\base.py", line 788, in send_task
    amqp.send_task_message(P, name, message, **options)
  File "C:\Users\Dmitr\PycharmProjects\project_dir\Lena\lib\site-packages\celery\app\amqp.py", line 510, in send_task_message
    ret = producer.publish(
  File "C:\Users\Dmitr\PycharmProjects\project_dir\Lena\lib\site-packages\kombu\messaging.py", line 177, in publish
    return _publish(
  File "C:\Users\Dmitr\PycharmProjects\project_dir\Lena\lib\site-packages\kombu\connection.py", line 523, in _ensured
    return fun(*args, **kwargs)
  File "C:\Users\Dmitr\PycharmProjects\project_dir\Lena\lib\site-packages\kombu\messaging.py", line 186, in _publish
    channel = self.channel
  File "C:\Users\Dmitr\PycharmProjects\project_dir\Lena\lib\site-packages\kombu\messaging.py", line 209, in _get_channel
    channel = self._channel = channel()
  File "C:\Users\Dmitr\PycharmProjects\project_dir\Lena\lib\site-packages\kombu\utils\functional.py", line 32, in __call__
    value = self.__value__ = self.__contract__()
  File "C:\Users\Dmitr\PycharmProjects\project_dir\Lena\lib\site-packages\kombu\messaging.py", line 225, in <lambda>
    channel = ChannelPromise(lambda: connection.default_channel)
  File "C:\Users\Dmitr\PycharmProjects\project_dir\Lena\lib\site-packages\kombu\connection.py", line 895, in default_channel
    self._ensure_connection(**conn_opts)
  File "C:\Users\Dmitr\PycharmProjects\project_dir\Lena\lib\site-packages\kombu\connection.py", line 433, in _ensure_connection
    return retry_over_time(
  File "C:\Users\Dmitr\AppData\Local\Programs\Python\Python39\lib\contextlib.py", line 135, in __exit__
    self.gen.throw(type, value, traceback)
  File "C:\Users\Dmitr\PycharmProjects\project_dir\Lena\lib\site-packages\kombu\connection.py", line 450, in _reraise_as_library_errors
    raise ConnectionError(str(exc)) from exc
kombu.exceptions.OperationalError: Error while reading from redis-14545.c266.us-east-1-3.ec2.cloud.redislabs.com:14545 : (10054, 'Удаленный хост принудительно разорвал существующее подключение', None, 10054, None)
2023-03-29 21:43:36,371 ERROR Internal Server Error: /news/articles/45/edit/ C:\Users\Dmitr\PycharmProjects\project_dir\Lena\lib\site-packages\django\utils\log.py (<class 'kombu.exceptions.OperationalError'>, OperationalError("Error while reading from redis-14545.c266.us-east-1-3.ec2.cloud.redislabs.com:14545 : (10054, 'Удаленный хост принудительно разорвал существующее подключение', None, 10054, None)"), <traceback object at 0x000001B38EBBC100>)
Traceback (most recent call last):
  File "C:\Users\Dmitr\PycharmProjects\project_dir\Lena\lib\site-packages\kombu\utils\functional.py", line 30, in __call__
    return self.__value__
AttributeError: 'ChannelPromise' object has no attribute '__value__'

During handling of the above exception, another exception occurred:

Traceback (most recent call last):
  File "C:\Users\Dmitr\PycharmProjects\project_dir\Lena\lib\site-packages\kombu\transport\virtual\base.py", line 925, in create_channel
    return self._avail_channels.pop()
IndexError: pop from empty list

During handling of the above exception, another exception occurred:

Traceback (most recent call last):
  File "C:\Users\Dmitr\PycharmProjects\project_dir\Lena\lib\site-packages\redis\connection.py", line 940, in read_response
    response = self._parser.read_response(disable_decoding=disable_decoding)
  File "C:\Users\Dmitr\PycharmProjects\project_dir\Lena\lib\site-packages\redis\connection.py", line 345, in read_response
    result = self._read_response(disable_decoding=disable_decoding)
  File "C:\Users\Dmitr\PycharmProjects\project_dir\Lena\lib\site-packages\redis\connection.py", line 355, in _read_response
    raw = self._buffer.readline()
  File "C:\Users\Dmitr\PycharmProjects\project_dir\Lena\lib\site-packages\redis\connection.py", line 258, in readline
    self._read_from_socket()
  File "C:\Users\Dmitr\PycharmProjects\project_dir\Lena\lib\site-packages\redis\connection.py", line 208, in _read_from_socket
    data = self._sock.recv(socket_read_size)
ConnectionResetError: [WinError 10054] Удаленный хост принудительно разорвал существующее подключение

During handling of the above exception, another exception occurred:

Traceback (most recent call last):
  File "C:\Users\Dmitr\PycharmProjects\project_dir\Lena\lib\site-packages\kombu\connection.py", line 446, in _reraise_as_library_errors
    yield
  File "C:\Users\Dmitr\PycharmProjects\project_dir\Lena\lib\site-packages\kombu\connection.py", line 433, in _ensure_connection
    return retry_over_time(
  File "C:\Users\Dmitr\PycharmProjects\project_dir\Lena\lib\site-packages\kombu\utils\functional.py", line 312, in retry_over_time
    return fun(*args, **kwargs)
  File "C:\Users\Dmitr\PycharmProjects\project_dir\Lena\lib\site-packages\kombu\connection.py", line 877, in _connection_factory
    self._connection = self._establish_connection()
  File "C:\Users\Dmitr\PycharmProjects\project_dir\Lena\lib\site-packages\kombu\connection.py", line 812, in _establish_connection
    conn = self.transport.establish_connection()
  File "C:\Users\Dmitr\PycharmProjects\project_dir\Lena\lib\site-packages\kombu\transport\virtual\base.py", line 949, in establish_connection
    self._avail_channels.append(self.create_channel(self))
  File "C:\Users\Dmitr\PycharmProjects\project_dir\Lena\lib\site-packages\kombu\transport\virtual\base.py", line 927, in create_channel
    channel = self.Channel(connection)
  File "C:\Users\Dmitr\PycharmProjects\project_dir\Lena\lib\site-packages\kombu\transport\redis.py", line 737, in __init__
    self.client.ping()
  File "C:\Users\Dmitr\PycharmProjects\project_dir\Lena\lib\site-packages\redis\commands\core.py", line 1194, in ping
    return self.execute_command("PING", **kwargs)
  File "C:\Users\Dmitr\PycharmProjects\project_dir\Lena\lib\site-packages\redis\client.py", line 1258, in execute_command
    return conn.retry.call_with_retry(
  File "C:\Users\Dmitr\PycharmProjects\project_dir\Lena\lib\site-packages\redis\retry.py", line 49, in call_with_retry
    fail(error)
  File "C:\Users\Dmitr\PycharmProjects\project_dir\Lena\lib\site-packages\redis\client.py", line 1262, in <lambda>
    lambda error: self._disconnect_raise(conn, error),
  File "C:\Users\Dmitr\PycharmProjects\project_dir\Lena\lib\site-packages\redis\client.py", line 1248, in _disconnect_raise
    raise error
  File "C:\Users\Dmitr\PycharmProjects\project_dir\Lena\lib\site-packages\redis\retry.py", line 46, in call_with_retry
    return do()
  File "C:\Users\Dmitr\PycharmProjects\project_dir\Lena\lib\site-packages\redis\client.py", line 1259, in <lambda>
    lambda: self._send_command_parse_response(
  File "C:\Users\Dmitr\PycharmProjects\project_dir\Lena\lib\site-packages\redis\client.py", line 1235, in _send_command_parse_response
    return self.parse_response(conn, command_name, **options)
  File "C:\Users\Dmitr\PycharmProjects\project_dir\Lena\lib\site-packages\redis\client.py", line 1275, in parse_response
    response = connection.read_response()
  File "C:\Users\Dmitr\PycharmProjects\project_dir\Lena\lib\site-packages\redis\connection.py", line 946, in read_response
    raise ConnectionError(
redis.exceptions.ConnectionError: Error while reading from redis-14545.c266.us-east-1-3.ec2.cloud.redislabs.com:14545 : (10054, 'Удаленный хост принудительно разорвал существующее подключение', None, 10054, None)

The above exception was the direct cause of the following exception:

Traceback (most recent call last):
  File "C:\Users\Dmitr\PycharmProjects\project_dir\Lena\lib\site-packages\django\core\handlers\exception.py", line 55, in inner
    response = get_response(request)
  File "C:\Users\Dmitr\PycharmProjects\project_dir\Lena\lib\site-packages\django\core\handlers\base.py", line 197, in _get_response
    response = wrapped_callback(request, *callback_args, **callback_kwargs)
  File "C:\Users\Dmitr\PycharmProjects\project_dir\Lena\lib\site-packages\django\views\generic\base.py", line 103, in view
    return self.dispatch(request, *args, **kwargs)
  File "C:\Users\Dmitr\PycharmProjects\project_dir\Lena\lib\site-packages\django\contrib\auth\mixins.py", line 109, in dispatch
    return super().dispatch(request, *args, **kwargs)
  File "C:\Users\Dmitr\PycharmProjects\project_dir\Lena\lib\site-packages\django\views\generic\base.py", line 142, in dispatch
    return handler(request, *args, **kwargs)
  File "C:\Users\Dmitr\PycharmProjects\project_dir\Lena\lib\site-packages\django\views\generic\edit.py", line 208, in post
    return super().post(request, *args, **kwargs)
  File "C:\Users\Dmitr\PycharmProjects\project_dir\Lena\lib\site-packages\django\views\generic\edit.py", line 153, in post
    return self.form_valid(form)
  File "C:\Users\Dmitr\PycharmProjects\project_dir\NewsPaper\News\views.py", line 98, in form_valid
    return super().form_valid(form)
  File "C:\Users\Dmitr\PycharmProjects\project_dir\Lena\lib\site-packages\django\views\generic\edit.py", line 135, in form_valid
    self.object = form.save()
  File "C:\Users\Dmitr\PycharmProjects\project_dir\Lena\lib\site-packages\django\forms\models.py", line 549, in save
    self._save_m2m()
  File "C:\Users\Dmitr\PycharmProjects\project_dir\Lena\lib\site-packages\django\forms\models.py", line 530, in _save_m2m
    f.save_form_data(self.instance, cleaned_data[f.name])
  File "C:\Users\Dmitr\PycharmProjects\project_dir\Lena\lib\site-packages\django\db\models\fields\related.py", line 1966, in save_form_data
    getattr(instance, self.attname).set(data)
  File "C:\Users\Dmitr\PycharmProjects\project_dir\Lena\lib\site-packages\django\db\models\fields\related_descriptors.py", line 1169, in set
    self.add(*new_objs, through_defaults=through_defaults)
  File "C:\Users\Dmitr\PycharmProjects\project_dir\Lena\lib\site-packages\django\db\models\fields\related_descriptors.py", line 1087, in add
    self._add_items(
  File "C:\Users\Dmitr\PycharmProjects\project_dir\Lena\lib\site-packages\django\db\models\fields\related_descriptors.py", line 1373, in _add_items
    signals.m2m_changed.send(
  File "C:\Users\Dmitr\PycharmProjects\project_dir\Lena\lib\site-packages\django\dispatch\dispatcher.py", line 176, in send
    return [
  File "C:\Users\Dmitr\PycharmProjects\project_dir\Lena\lib\site-packages\django\dispatch\dispatcher.py", line 177, in <listcomp>
    (receiver, receiver(signal=self, sender=sender, **named))
  File "C:\Users\Dmitr\PycharmProjects\project_dir\NewsPaper\News\signals.py", line 14, in notif_subs
    post_created.apply_async((instance.id, instance.title, instance.text),
  File "C:\Users\Dmitr\PycharmProjects\project_dir\Lena\lib\site-packages\celery\app\task.py", line 575, in apply_async
    return app.send_task(
  File "C:\Users\Dmitr\PycharmProjects\project_dir\Lena\lib\site-packages\celery\app\base.py", line 788, in send_task
    amqp.send_task_message(P, name, message, **options)
  File "C:\Users\Dmitr\PycharmProjects\project_dir\Lena\lib\site-packages\celery\app\amqp.py", line 510, in send_task_message
    ret = producer.publish(
  File "C:\Users\Dmitr\PycharmProjects\project_dir\Lena\lib\site-packages\kombu\messaging.py", line 177, in publish
    return _publish(
  File "C:\Users\Dmitr\PycharmProjects\project_dir\Lena\lib\site-packages\kombu\connection.py", line 523, in _ensured
    return fun(*args, **kwargs)
  File "C:\Users\Dmitr\PycharmProjects\project_dir\Lena\lib\site-packages\kombu\messaging.py", line 186, in _publish
    channel = self.channel
  File "C:\Users\Dmitr\PycharmProjects\project_dir\Lena\lib\site-packages\kombu\messaging.py", line 209, in _get_channel
    channel = self._channel = channel()
  File "C:\Users\Dmitr\PycharmProjects\project_dir\Lena\lib\site-packages\kombu\utils\functional.py", line 32, in __call__
    value = self.__value__ = self.__contract__()
  File "C:\Users\Dmitr\PycharmProjects\project_dir\Lena\lib\site-packages\kombu\messaging.py", line 225, in <lambda>
    channel = ChannelPromise(lambda: connection.default_channel)
  File "C:\Users\Dmitr\PycharmProjects\project_dir\Lena\lib\site-packages\kombu\connection.py", line 895, in default_channel
    self._ensure_connection(**conn_opts)
  File "C:\Users\Dmitr\PycharmProjects\project_dir\Lena\lib\site-packages\kombu\connection.py", line 433, in _ensure_connection
    return retry_over_time(
  File "C:\Users\Dmitr\AppData\Local\Programs\Python\Python39\lib\contextlib.py", line 135, in __exit__
    self.gen.throw(type, value, traceback)
  File "C:\Users\Dmitr\PycharmProjects\project_dir\Lena\lib\site-packages\kombu\connection.py", line 450, in _reraise_as_library_errors
    raise ConnectionError(str(exc)) from exc
kombu.exceptions.OperationalError: Error while reading from redis-14545.c266.us-east-1-3.ec2.cloud.redislabs.com:14545 : (10054, 'Удаленный хост принудительно разорвал существующее подключение', None, 10054, None)
2023-03-29 21:43:36,387 ERROR "POST /news/articles/45/edit/ HTTP/1.1" 500 352717 C:\Users\Dmitr\PycharmProjects\project_dir\Lena\lib\site-packages\django\core\servers\basehttp.py None
2023-03-29 21:44:23,737 ERROR Internal Server Error: /news/articles/44/edit/ C:\Users\Dmitr\PycharmProjects\project_dir\Lena\lib\site-packages\django\utils\log.py (<class 'kombu.exceptions.OperationalError'>, OperationalError("Error while reading from redis-14545.c266.us-east-1-3.ec2.cloud.redislabs.com:14545 : (10054, 'Удаленный хост принудительно разорвал существующее подключение', None, 10054, None)"), <traceback object at 0x000001B38D7EFC80>)
Traceback (most recent call last):
  File "C:\Users\Dmitr\PycharmProjects\project_dir\Lena\lib\site-packages\kombu\utils\functional.py", line 30, in __call__
    return self.__value__
AttributeError: 'ChannelPromise' object has no attribute '__value__'

During handling of the above exception, another exception occurred:

Traceback (most recent call last):
  File "C:\Users\Dmitr\PycharmProjects\project_dir\Lena\lib\site-packages\kombu\transport\virtual\base.py", line 925, in create_channel
    return self._avail_channels.pop()
IndexError: pop from empty list

During handling of the above exception, another exception occurred:

Traceback (most recent call last):
  File "C:\Users\Dmitr\PycharmProjects\project_dir\Lena\lib\site-packages\redis\connection.py", line 940, in read_response
    response = self._parser.read_response(disable_decoding=disable_decoding)
  File "C:\Users\Dmitr\PycharmProjects\project_dir\Lena\lib\site-packages\redis\connection.py", line 345, in read_response
    result = self._read_response(disable_decoding=disable_decoding)
  File "C:\Users\Dmitr\PycharmProjects\project_dir\Lena\lib\site-packages\redis\connection.py", line 355, in _read_response
    raw = self._buffer.readline()
  File "C:\Users\Dmitr\PycharmProjects\project_dir\Lena\lib\site-packages\redis\connection.py", line 258, in readline
    self._read_from_socket()
  File "C:\Users\Dmitr\PycharmProjects\project_dir\Lena\lib\site-packages\redis\connection.py", line 208, in _read_from_socket
    data = self._sock.recv(socket_read_size)
ConnectionResetError: [WinError 10054] Удаленный хост принудительно разорвал существующее подключение

During handling of the above exception, another exception occurred:

Traceback (most recent call last):
  File "C:\Users\Dmitr\PycharmProjects\project_dir\Lena\lib\site-packages\kombu\connection.py", line 446, in _reraise_as_library_errors
    yield
  File "C:\Users\Dmitr\PycharmProjects\project_dir\Lena\lib\site-packages\kombu\connection.py", line 433, in _ensure_connection
    return retry_over_time(
  File "C:\Users\Dmitr\PycharmProjects\project_dir\Lena\lib\site-packages\kombu\utils\functional.py", line 312, in retry_over_time
    return fun(*args, **kwargs)
  File "C:\Users\Dmitr\PycharmProjects\project_dir\Lena\lib\site-packages\kombu\connection.py", line 877, in _connection_factory
    self._connection = self._establish_connection()
  File "C:\Users\Dmitr\PycharmProjects\project_dir\Lena\lib\site-packages\kombu\connection.py", line 812, in _establish_connection
    conn = self.transport.establish_connection()
  File "C:\Users\Dmitr\PycharmProjects\project_dir\Lena\lib\site-packages\kombu\transport\virtual\base.py", line 949, in establish_connection
    self._avail_channels.append(self.create_channel(self))
  File "C:\Users\Dmitr\PycharmProjects\project_dir\Lena\lib\site-packages\kombu\transport\virtual\base.py", line 927, in create_channel
    channel = self.Channel(connection)
  File "C:\Users\Dmitr\PycharmProjects\project_dir\Lena\lib\site-packages\kombu\transport\redis.py", line 737, in __init__
    self.client.ping()
  File "C:\Users\Dmitr\PycharmProjects\project_dir\Lena\lib\site-packages\redis\commands\core.py", line 1194, in ping
    return self.execute_command("PING", **kwargs)
  File "C:\Users\Dmitr\PycharmProjects\project_dir\Lena\lib\site-packages\redis\client.py", line 1258, in execute_command
    return conn.retry.call_with_retry(
  File "C:\Users\Dmitr\PycharmProjects\project_dir\Lena\lib\site-packages\redis\retry.py", line 49, in call_with_retry
    fail(error)
  File "C:\Users\Dmitr\PycharmProjects\project_dir\Lena\lib\site-packages\redis\client.py", line 1262, in <lambda>
    lambda error: self._disconnect_raise(conn, error),
  File "C:\Users\Dmitr\PycharmProjects\project_dir\Lena\lib\site-packages\redis\client.py", line 1248, in _disconnect_raise
    raise error
  File "C:\Users\Dmitr\PycharmProjects\project_dir\Lena\lib\site-packages\redis\retry.py", line 46, in call_with_retry
    return do()
  File "C:\Users\Dmitr\PycharmProjects\project_dir\Lena\lib\site-packages\redis\client.py", line 1259, in <lambda>
    lambda: self._send_command_parse_response(
  File "C:\Users\Dmitr\PycharmProjects\project_dir\Lena\lib\site-packages\redis\client.py", line 1235, in _send_command_parse_response
    return self.parse_response(conn, command_name, **options)
  File "C:\Users\Dmitr\PycharmProjects\project_dir\Lena\lib\site-packages\redis\client.py", line 1275, in parse_response
    response = connection.read_response()
  File "C:\Users\Dmitr\PycharmProjects\project_dir\Lena\lib\site-packages\redis\connection.py", line 946, in read_response
    raise ConnectionError(
redis.exceptions.ConnectionError: Error while reading from redis-14545.c266.us-east-1-3.ec2.cloud.redislabs.com:14545 : (10054, 'Удаленный хост принудительно разорвал существующее подключение', None, 10054, None)

The above exception was the direct cause of the following exception:

Traceback (most recent call last):
  File "C:\Users\Dmitr\PycharmProjects\project_dir\Lena\lib\site-packages\django\core\handlers\exception.py", line 55, in inner
    response = get_response(request)
  File "C:\Users\Dmitr\PycharmProjects\project_dir\Lena\lib\site-packages\django\core\handlers\base.py", line 197, in _get_response
    response = wrapped_callback(request, *callback_args, **callback_kwargs)
  File "C:\Users\Dmitr\PycharmProjects\project_dir\Lena\lib\site-packages\django\views\generic\base.py", line 103, in view
    return self.dispatch(request, *args, **kwargs)
  File "C:\Users\Dmitr\PycharmProjects\project_dir\Lena\lib\site-packages\django\contrib\auth\mixins.py", line 109, in dispatch
    return super().dispatch(request, *args, **kwargs)
  File "C:\Users\Dmitr\PycharmProjects\project_dir\Lena\lib\site-packages\django\views\generic\base.py", line 142, in dispatch
    return handler(request, *args, **kwargs)
  File "C:\Users\Dmitr\PycharmProjects\project_dir\Lena\lib\site-packages\django\views\generic\edit.py", line 208, in post
    return super().post(request, *args, **kwargs)
  File "C:\Users\Dmitr\PycharmProjects\project_dir\Lena\lib\site-packages\django\views\generic\edit.py", line 153, in post
    return self.form_valid(form)
  File "C:\Users\Dmitr\PycharmProjects\project_dir\NewsPaper\News\views.py", line 98, in form_valid
    return super().form_valid(form)
  File "C:\Users\Dmitr\PycharmProjects\project_dir\Lena\lib\site-packages\django\views\generic\edit.py", line 135, in form_valid
    self.object = form.save()
  File "C:\Users\Dmitr\PycharmProjects\project_dir\Lena\lib\site-packages\django\forms\models.py", line 549, in save
    self._save_m2m()
  File "C:\Users\Dmitr\PycharmProjects\project_dir\Lena\lib\site-packages\django\forms\models.py", line 530, in _save_m2m
    f.save_form_data(self.instance, cleaned_data[f.name])
  File "C:\Users\Dmitr\PycharmProjects\project_dir\Lena\lib\site-packages\django\db\models\fields\related.py", line 1966, in save_form_data
    getattr(instance, self.attname).set(data)
  File "C:\Users\Dmitr\PycharmProjects\project_dir\Lena\lib\site-packages\django\db\models\fields\related_descriptors.py", line 1169, in set
    self.add(*new_objs, through_defaults=through_defaults)
  File "C:\Users\Dmitr\PycharmProjects\project_dir\Lena\lib\site-packages\django\db\models\fields\related_descriptors.py", line 1087, in add
    self._add_items(
  File "C:\Users\Dmitr\PycharmProjects\project_dir\Lena\lib\site-packages\django\db\models\fields\related_descriptors.py", line 1373, in _add_items
    signals.m2m_changed.send(
  File "C:\Users\Dmitr\PycharmProjects\project_dir\Lena\lib\site-packages\django\dispatch\dispatcher.py", line 176, in send
    return [
  File "C:\Users\Dmitr\PycharmProjects\project_dir\Lena\lib\site-packages\django\dispatch\dispatcher.py", line 177, in <listcomp>
    (receiver, receiver(signal=self, sender=sender, **named))
  File "C:\Users\Dmitr\PycharmProjects\project_dir\NewsPaper\News\signals.py", line 14, in notif_subs
    post_created.apply_async((instance.id, instance.title, instance.text),
  File "C:\Users\Dmitr\PycharmProjects\project_dir\Lena\lib\site-packages\celery\app\task.py", line 575, in apply_async
    return app.send_task(
  File "C:\Users\Dmitr\PycharmProjects\project_dir\Lena\lib\site-packages\celery\app\base.py", line 788, in send_task
    amqp.send_task_message(P, name, message, **options)
  File "C:\Users\Dmitr\PycharmProjects\project_dir\Lena\lib\site-packages\celery\app\amqp.py", line 510, in send_task_message
    ret = producer.publish(
  File "C:\Users\Dmitr\PycharmProjects\project_dir\Lena\lib\site-packages\kombu\messaging.py", line 177, in publish
    return _publish(
  File "C:\Users\Dmitr\PycharmProjects\project_dir\Lena\lib\site-packages\kombu\connection.py", line 523, in _ensured
    return fun(*args, **kwargs)
  File "C:\Users\Dmitr\PycharmProjects\project_dir\Lena\lib\site-packages\kombu\messaging.py", line 186, in _publish
    channel = self.channel
  File "C:\Users\Dmitr\PycharmProjects\project_dir\Lena\lib\site-packages\kombu\messaging.py", line 209, in _get_channel
    channel = self._channel = channel()
  File "C:\Users\Dmitr\PycharmProjects\project_dir\Lena\lib\site-packages\kombu\utils\functional.py", line 32, in __call__
    value = self.__value__ = self.__contract__()
  File "C:\Users\Dmitr\PycharmProjects\project_dir\Lena\lib\site-packages\kombu\messaging.py", line 225, in <lambda>
    channel = ChannelPromise(lambda: connection.default_channel)
  File "C:\Users\Dmitr\PycharmProjects\project_dir\Lena\lib\site-packages\kombu\connection.py", line 895, in default_channel
    self._ensure_connection(**conn_opts)
  File "C:\Users\Dmitr\PycharmProjects\project_dir\Lena\lib\site-packages\kombu\connection.py", line 433, in _ensure_connection
    return retry_over_time(
  File "C:\Users\Dmitr\AppData\Local\Programs\Python\Python39\lib\contextlib.py", line 135, in __exit__
    self.gen.throw(type, value, traceback)
  File "C:\Users\Dmitr\PycharmProjects\project_dir\Lena\lib\site-packages\kombu\connection.py", line 450, in _reraise_as_library_errors
    raise ConnectionError(str(exc)) from exc
kombu.exceptions.OperationalError: Error while reading from redis-14545.c266.us-east-1-3.ec2.cloud.redislabs.com:14545 : (10054, 'Удаленный хост принудительно разорвал существующее подключение', None, 10054, None)
2023-03-29 21:44:23,753 ERROR "POST /news/articles/44/edit/ HTTP/1.1" 500 352724 C:\Users\Dmitr\PycharmProjects\project_dir\Lena\lib\site-packages\django\core\servers\basehttp.py None
2023-03-29 21:44:42,364 ERROR Internal Server Error: /news/articles/44/edit/ C:\Users\Dmitr\PycharmProjects\project_dir\Lena\lib\site-packages\django\utils\log.py (<class 'kombu.exceptions.OperationalError'>, OperationalError("Error while reading from redis-14545.c266.us-east-1-3.ec2.cloud.redislabs.com:14545 : (10054, 'Удаленный хост принудительно разорвал существующее подключение', None, 10054, None)"), <traceback object at 0x000001B38EBCD980>)
Traceback (most recent call last):
  File "C:\Users\Dmitr\PycharmProjects\project_dir\Lena\lib\site-packages\kombu\utils\functional.py", line 30, in __call__
    return self.__value__
AttributeError: 'ChannelPromise' object has no attribute '__value__'

During handling of the above exception, another exception occurred:

Traceback (most recent call last):
  File "C:\Users\Dmitr\PycharmProjects\project_dir\Lena\lib\site-packages\kombu\transport\virtual\base.py", line 925, in create_channel
    return self._avail_channels.pop()
IndexError: pop from empty list

During handling of the above exception, another exception occurred:

Traceback (most recent call last):
  File "C:\Users\Dmitr\PycharmProjects\project_dir\Lena\lib\site-packages\redis\connection.py", line 940, in read_response
    response = self._parser.read_response(disable_decoding=disable_decoding)
  File "C:\Users\Dmitr\PycharmProjects\project_dir\Lena\lib\site-packages\redis\connection.py", line 345, in read_response
    result = self._read_response(disable_decoding=disable_decoding)
  File "C:\Users\Dmitr\PycharmProjects\project_dir\Lena\lib\site-packages\redis\connection.py", line 355, in _read_response
    raw = self._buffer.readline()
  File "C:\Users\Dmitr\PycharmProjects\project_dir\Lena\lib\site-packages\redis\connection.py", line 258, in readline
    self._read_from_socket()
  File "C:\Users\Dmitr\PycharmProjects\project_dir\Lena\lib\site-packages\redis\connection.py", line 208, in _read_from_socket
    data = self._sock.recv(socket_read_size)
ConnectionResetError: [WinError 10054] Удаленный хост принудительно разорвал существующее подключение

During handling of the above exception, another exception occurred:

Traceback (most recent call last):
  File "C:\Users\Dmitr\PycharmProjects\project_dir\Lena\lib\site-packages\kombu\connection.py", line 446, in _reraise_as_library_errors
    yield
  File "C:\Users\Dmitr\PycharmProjects\project_dir\Lena\lib\site-packages\kombu\connection.py", line 433, in _ensure_connection
    return retry_over_time(
  File "C:\Users\Dmitr\PycharmProjects\project_dir\Lena\lib\site-packages\kombu\utils\functional.py", line 312, in retry_over_time
    return fun(*args, **kwargs)
  File "C:\Users\Dmitr\PycharmProjects\project_dir\Lena\lib\site-packages\kombu\connection.py", line 877, in _connection_factory
    self._connection = self._establish_connection()
  File "C:\Users\Dmitr\PycharmProjects\project_dir\Lena\lib\site-packages\kombu\connection.py", line 812, in _establish_connection
    conn = self.transport.establish_connection()
  File "C:\Users\Dmitr\PycharmProjects\project_dir\Lena\lib\site-packages\kombu\transport\virtual\base.py", line 949, in establish_connection
    self._avail_channels.append(self.create_channel(self))
  File "C:\Users\Dmitr\PycharmProjects\project_dir\Lena\lib\site-packages\kombu\transport\virtual\base.py", line 927, in create_channel
    channel = self.Channel(connection)
  File "C:\Users\Dmitr\PycharmProjects\project_dir\Lena\lib\site-packages\kombu\transport\redis.py", line 737, in __init__
    self.client.ping()
  File "C:\Users\Dmitr\PycharmProjects\project_dir\Lena\lib\site-packages\redis\commands\core.py", line 1194, in ping
    return self.execute_command("PING", **kwargs)
  File "C:\Users\Dmitr\PycharmProjects\project_dir\Lena\lib\site-packages\redis\client.py", line 1258, in execute_command
    return conn.retry.call_with_retry(
  File "C:\Users\Dmitr\PycharmProjects\project_dir\Lena\lib\site-packages\redis\retry.py", line 49, in call_with_retry
    fail(error)
  File "C:\Users\Dmitr\PycharmProjects\project_dir\Lena\lib\site-packages\redis\client.py", line 1262, in <lambda>
    lambda error: self._disconnect_raise(conn, error),
  File "C:\Users\Dmitr\PycharmProjects\project_dir\Lena\lib\site-packages\redis\client.py", line 1248, in _disconnect_raise
    raise error
  File "C:\Users\Dmitr\PycharmProjects\project_dir\Lena\lib\site-packages\redis\retry.py", line 46, in call_with_retry
    return do()
  File "C:\Users\Dmitr\PycharmProjects\project_dir\Lena\lib\site-packages\redis\client.py", line 1259, in <lambda>
    lambda: self._send_command_parse_response(
  File "C:\Users\Dmitr\PycharmProjects\project_dir\Lena\lib\site-packages\redis\client.py", line 1235, in _send_command_parse_response
    return self.parse_response(conn, command_name, **options)
  File "C:\Users\Dmitr\PycharmProjects\project_dir\Lena\lib\site-packages\redis\client.py", line 1275, in parse_response
    response = connection.read_response()
  File "C:\Users\Dmitr\PycharmProjects\project_dir\Lena\lib\site-packages\redis\connection.py", line 946, in read_response
    raise ConnectionError(
redis.exceptions.ConnectionError: Error while reading from redis-14545.c266.us-east-1-3.ec2.cloud.redislabs.com:14545 : (10054, 'Удаленный хост принудительно разорвал существующее подключение', None, 10054, None)

The above exception was the direct cause of the following exception:

Traceback (most recent call last):
  File "C:\Users\Dmitr\PycharmProjects\project_dir\Lena\lib\site-packages\django\core\handlers\exception.py", line 55, in inner
    response = get_response(request)
  File "C:\Users\Dmitr\PycharmProjects\project_dir\Lena\lib\site-packages\django\core\handlers\base.py", line 197, in _get_response
    response = wrapped_callback(request, *callback_args, **callback_kwargs)
  File "C:\Users\Dmitr\PycharmProjects\project_dir\Lena\lib\site-packages\django\views\generic\base.py", line 103, in view
    return self.dispatch(request, *args, **kwargs)
  File "C:\Users\Dmitr\PycharmProjects\project_dir\Lena\lib\site-packages\django\contrib\auth\mixins.py", line 109, in dispatch
    return super().dispatch(request, *args, **kwargs)
  File "C:\Users\Dmitr\PycharmProjects\project_dir\Lena\lib\site-packages\django\views\generic\base.py", line 142, in dispatch
    return handler(request, *args, **kwargs)
  File "C:\Users\Dmitr\PycharmProjects\project_dir\Lena\lib\site-packages\django\views\generic\edit.py", line 208, in post
    return super().post(request, *args, **kwargs)
  File "C:\Users\Dmitr\PycharmProjects\project_dir\Lena\lib\site-packages\django\views\generic\edit.py", line 153, in post
    return self.form_valid(form)
  File "C:\Users\Dmitr\PycharmProjects\project_dir\NewsPaper\News\views.py", line 98, in form_valid
    return super().form_valid(form)
  File "C:\Users\Dmitr\PycharmProjects\project_dir\Lena\lib\site-packages\django\views\generic\edit.py", line 135, in form_valid
    self.object = form.save()
  File "C:\Users\Dmitr\PycharmProjects\project_dir\Lena\lib\site-packages\django\forms\models.py", line 549, in save
    self._save_m2m()
  File "C:\Users\Dmitr\PycharmProjects\project_dir\Lena\lib\site-packages\django\forms\models.py", line 530, in _save_m2m
    f.save_form_data(self.instance, cleaned_data[f.name])
  File "C:\Users\Dmitr\PycharmProjects\project_dir\Lena\lib\site-packages\django\db\models\fields\related.py", line 1966, in save_form_data
    getattr(instance, self.attname).set(data)
  File "C:\Users\Dmitr\PycharmProjects\project_dir\Lena\lib\site-packages\django\db\models\fields\related_descriptors.py", line 1169, in set
    self.add(*new_objs, through_defaults=through_defaults)
  File "C:\Users\Dmitr\PycharmProjects\project_dir\Lena\lib\site-packages\django\db\models\fields\related_descriptors.py", line 1087, in add
    self._add_items(
  File "C:\Users\Dmitr\PycharmProjects\project_dir\Lena\lib\site-packages\django\db\models\fields\related_descriptors.py", line 1373, in _add_items
    signals.m2m_changed.send(
  File "C:\Users\Dmitr\PycharmProjects\project_dir\Lena\lib\site-packages\django\dispatch\dispatcher.py", line 176, in send
    return [
  File "C:\Users\Dmitr\PycharmProjects\project_dir\Lena\lib\site-packages\django\dispatch\dispatcher.py", line 177, in <listcomp>
    (receiver, receiver(signal=self, sender=sender, **named))
  File "C:\Users\Dmitr\PycharmProjects\project_dir\NewsPaper\News\signals.py", line 14, in notif_subs
    post_created.apply_async((instance.id, instance.title, instance.text),
  File "C:\Users\Dmitr\PycharmProjects\project_dir\Lena\lib\site-packages\celery\app\task.py", line 575, in apply_async
    return app.send_task(
  File "C:\Users\Dmitr\PycharmProjects\project_dir\Lena\lib\site-packages\celery\app\base.py", line 788, in send_task
    amqp.send_task_message(P, name, message, **options)
  File "C:\Users\Dmitr\PycharmProjects\project_dir\Lena\lib\site-packages\celery\app\amqp.py", line 510, in send_task_message
    ret = producer.publish(
  File "C:\Users\Dmitr\PycharmProjects\project_dir\Lena\lib\site-packages\kombu\messaging.py", line 177, in publish
    return _publish(
  File "C:\Users\Dmitr\PycharmProjects\project_dir\Lena\lib\site-packages\kombu\connection.py", line 523, in _ensured
    return fun(*args, **kwargs)
  File "C:\Users\Dmitr\PycharmProjects\project_dir\Lena\lib\site-packages\kombu\messaging.py", line 186, in _publish
    channel = self.channel
  File "C:\Users\Dmitr\PycharmProjects\project_dir\Lena\lib\site-packages\kombu\messaging.py", line 209, in _get_channel
    channel = self._channel = channel()
  File "C:\Users\Dmitr\PycharmProjects\project_dir\Lena\lib\site-packages\kombu\utils\functional.py", line 32, in __call__
    value = self.__value__ = self.__contract__()
  File "C:\Users\Dmitr\PycharmProjects\project_dir\Lena\lib\site-packages\kombu\messaging.py", line 225, in <lambda>
    channel = ChannelPromise(lambda: connection.default_channel)
  File "C:\Users\Dmitr\PycharmProjects\project_dir\Lena\lib\site-packages\kombu\connection.py", line 895, in default_channel
    self._ensure_connection(**conn_opts)
  File "C:\Users\Dmitr\PycharmProjects\project_dir\Lena\lib\site-packages\kombu\connection.py", line 433, in _ensure_connection
    return retry_over_time(
  File "C:\Users\Dmitr\AppData\Local\Programs\Python\Python39\lib\contextlib.py", line 135, in __exit__
    self.gen.throw(type, value, traceback)
  File "C:\Users\Dmitr\PycharmProjects\project_dir\Lena\lib\site-packages\kombu\connection.py", line 450, in _reraise_as_library_errors
    raise ConnectionError(str(exc)) from exc
kombu.exceptions.OperationalError: Error while reading from redis-14545.c266.us-east-1-3.ec2.cloud.redislabs.com:14545 : (10054, 'Удаленный хост принудительно разорвал существующее подключение', None, 10054, None)
2023-03-29 21:44:55,980 ERROR Internal Server Error: /news/news/43/edit/ C:\Users\Dmitr\PycharmProjects\project_dir\Lena\lib\site-packages\django\utils\log.py (<class 'kombu.exceptions.OperationalError'>, OperationalError("Error while reading from redis-14545.c266.us-east-1-3.ec2.cloud.redislabs.com:14545 : (10054, 'Удаленный хост принудительно разорвал существующее подключение', None, 10054, None)"), <traceback object at 0x000001B38EBBF180>)
Traceback (most recent call last):
  File "C:\Users\Dmitr\PycharmProjects\project_dir\Lena\lib\site-packages\kombu\utils\functional.py", line 30, in __call__
    return self.__value__
AttributeError: 'ChannelPromise' object has no attribute '__value__'

During handling of the above exception, another exception occurred:

Traceback (most recent call last):
  File "C:\Users\Dmitr\PycharmProjects\project_dir\Lena\lib\site-packages\kombu\transport\virtual\base.py", line 925, in create_channel
    return self._avail_channels.pop()
IndexError: pop from empty list

During handling of the above exception, another exception occurred:

Traceback (most recent call last):
  File "C:\Users\Dmitr\PycharmProjects\project_dir\Lena\lib\site-packages\redis\connection.py", line 940, in read_response
    response = self._parser.read_response(disable_decoding=disable_decoding)
  File "C:\Users\Dmitr\PycharmProjects\project_dir\Lena\lib\site-packages\redis\connection.py", line 345, in read_response
    result = self._read_response(disable_decoding=disable_decoding)
  File "C:\Users\Dmitr\PycharmProjects\project_dir\Lena\lib\site-packages\redis\connection.py", line 355, in _read_response
    raw = self._buffer.readline()
  File "C:\Users\Dmitr\PycharmProjects\project_dir\Lena\lib\site-packages\redis\connection.py", line 258, in readline
    self._read_from_socket()
  File "C:\Users\Dmitr\PycharmProjects\project_dir\Lena\lib\site-packages\redis\connection.py", line 208, in _read_from_socket
    data = self._sock.recv(socket_read_size)
ConnectionResetError: [WinError 10054] Удаленный хост принудительно разорвал существующее подключение

During handling of the above exception, another exception occurred:

Traceback (most recent call last):
  File "C:\Users\Dmitr\PycharmProjects\project_dir\Lena\lib\site-packages\kombu\connection.py", line 446, in _reraise_as_library_errors
    yield
  File "C:\Users\Dmitr\PycharmProjects\project_dir\Lena\lib\site-packages\kombu\connection.py", line 433, in _ensure_connection
    return retry_over_time(
  File "C:\Users\Dmitr\PycharmProjects\project_dir\Lena\lib\site-packages\kombu\utils\functional.py", line 312, in retry_over_time
    return fun(*args, **kwargs)
  File "C:\Users\Dmitr\PycharmProjects\project_dir\Lena\lib\site-packages\kombu\connection.py", line 877, in _connection_factory
    self._connection = self._establish_connection()
  File "C:\Users\Dmitr\PycharmProjects\project_dir\Lena\lib\site-packages\kombu\connection.py", line 812, in _establish_connection
    conn = self.transport.establish_connection()
  File "C:\Users\Dmitr\PycharmProjects\project_dir\Lena\lib\site-packages\kombu\transport\virtual\base.py", line 949, in establish_connection
    self._avail_channels.append(self.create_channel(self))
  File "C:\Users\Dmitr\PycharmProjects\project_dir\Lena\lib\site-packages\kombu\transport\virtual\base.py", line 927, in create_channel
    channel = self.Channel(connection)
  File "C:\Users\Dmitr\PycharmProjects\project_dir\Lena\lib\site-packages\kombu\transport\redis.py", line 737, in __init__
    self.client.ping()
  File "C:\Users\Dmitr\PycharmProjects\project_dir\Lena\lib\site-packages\redis\commands\core.py", line 1194, in ping
    return self.execute_command("PING", **kwargs)
  File "C:\Users\Dmitr\PycharmProjects\project_dir\Lena\lib\site-packages\redis\client.py", line 1258, in execute_command
    return conn.retry.call_with_retry(
  File "C:\Users\Dmitr\PycharmProjects\project_dir\Lena\lib\site-packages\redis\retry.py", line 49, in call_with_retry
    fail(error)
  File "C:\Users\Dmitr\PycharmProjects\project_dir\Lena\lib\site-packages\redis\client.py", line 1262, in <lambda>
    lambda error: self._disconnect_raise(conn, error),
  File "C:\Users\Dmitr\PycharmProjects\project_dir\Lena\lib\site-packages\redis\client.py", line 1248, in _disconnect_raise
    raise error
  File "C:\Users\Dmitr\PycharmProjects\project_dir\Lena\lib\site-packages\redis\retry.py", line 46, in call_with_retry
    return do()
  File "C:\Users\Dmitr\PycharmProjects\project_dir\Lena\lib\site-packages\redis\client.py", line 1259, in <lambda>
    lambda: self._send_command_parse_response(
  File "C:\Users\Dmitr\PycharmProjects\project_dir\Lena\lib\site-packages\redis\client.py", line 1235, in _send_command_parse_response
    return self.parse_response(conn, command_name, **options)
  File "C:\Users\Dmitr\PycharmProjects\project_dir\Lena\lib\site-packages\redis\client.py", line 1275, in parse_response
    response = connection.read_response()
  File "C:\Users\Dmitr\PycharmProjects\project_dir\Lena\lib\site-packages\redis\connection.py", line 946, in read_response
    raise ConnectionError(
redis.exceptions.ConnectionError: Error while reading from redis-14545.c266.us-east-1-3.ec2.cloud.redislabs.com:14545 : (10054, 'Удаленный хост принудительно разорвал существующее подключение', None, 10054, None)

The above exception was the direct cause of the following exception:

Traceback (most recent call last):
  File "C:\Users\Dmitr\PycharmProjects\project_dir\Lena\lib\site-packages\django\core\handlers\exception.py", line 55, in inner
    response = get_response(request)
  File "C:\Users\Dmitr\PycharmProjects\project_dir\Lena\lib\site-packages\django\core\handlers\base.py", line 197, in _get_response
    response = wrapped_callback(request, *callback_args, **callback_kwargs)
  File "C:\Users\Dmitr\PycharmProjects\project_dir\Lena\lib\site-packages\django\views\generic\base.py", line 103, in view
    return self.dispatch(request, *args, **kwargs)
  File "C:\Users\Dmitr\PycharmProjects\project_dir\Lena\lib\site-packages\django\contrib\auth\mixins.py", line 109, in dispatch
    return super().dispatch(request, *args, **kwargs)
  File "C:\Users\Dmitr\PycharmProjects\project_dir\Lena\lib\site-packages\django\views\generic\base.py", line 142, in dispatch
    return handler(request, *args, **kwargs)
  File "C:\Users\Dmitr\PycharmProjects\project_dir\Lena\lib\site-packages\django\views\generic\edit.py", line 208, in post
    return super().post(request, *args, **kwargs)
  File "C:\Users\Dmitr\PycharmProjects\project_dir\Lena\lib\site-packages\django\views\generic\edit.py", line 153, in post
    return self.form_valid(form)
  File "C:\Users\Dmitr\PycharmProjects\project_dir\NewsPaper\News\views.py", line 72, in form_valid
    return super().form_valid(form)
  File "C:\Users\Dmitr\PycharmProjects\project_dir\Lena\lib\site-packages\django\views\generic\edit.py", line 135, in form_valid
    self.object = form.save()
  File "C:\Users\Dmitr\PycharmProjects\project_dir\Lena\lib\site-packages\django\forms\models.py", line 549, in save
    self._save_m2m()
  File "C:\Users\Dmitr\PycharmProjects\project_dir\Lena\lib\site-packages\django\forms\models.py", line 530, in _save_m2m
    f.save_form_data(self.instance, cleaned_data[f.name])
  File "C:\Users\Dmitr\PycharmProjects\project_dir\Lena\lib\site-packages\django\db\models\fields\related.py", line 1966, in save_form_data
    getattr(instance, self.attname).set(data)
  File "C:\Users\Dmitr\PycharmProjects\project_dir\Lena\lib\site-packages\django\db\models\fields\related_descriptors.py", line 1169, in set
    self.add(*new_objs, through_defaults=through_defaults)
  File "C:\Users\Dmitr\PycharmProjects\project_dir\Lena\lib\site-packages\django\db\models\fields\related_descriptors.py", line 1087, in add
    self._add_items(
  File "C:\Users\Dmitr\PycharmProjects\project_dir\Lena\lib\site-packages\django\db\models\fields\related_descriptors.py", line 1373, in _add_items
    signals.m2m_changed.send(
  File "C:\Users\Dmitr\PycharmProjects\project_dir\Lena\lib\site-packages\django\dispatch\dispatcher.py", line 176, in send
    return [
  File "C:\Users\Dmitr\PycharmProjects\project_dir\Lena\lib\site-packages\django\dispatch\dispatcher.py", line 177, in <listcomp>
    (receiver, receiver(signal=self, sender=sender, **named))
  File "C:\Users\Dmitr\PycharmProjects\project_dir\NewsPaper\News\signals.py", line 14, in notif_subs
    post_created.apply_async((instance.id, instance.title, instance.text),
  File "C:\Users\Dmitr\PycharmProjects\project_dir\Lena\lib\site-packages\celery\app\task.py", line 575, in apply_async
    return app.send_task(
  File "C:\Users\Dmitr\PycharmProjects\project_dir\Lena\lib\site-packages\celery\app\base.py", line 788, in send_task
    amqp.send_task_message(P, name, message, **options)
  File "C:\Users\Dmitr\PycharmProjects\project_dir\Lena\lib\site-packages\celery\app\amqp.py", line 510, in send_task_message
    ret = producer.publish(
  File "C:\Users\Dmitr\PycharmProjects\project_dir\Lena\lib\site-packages\kombu\messaging.py", line 177, in publish
    return _publish(
  File "C:\Users\Dmitr\PycharmProjects\project_dir\Lena\lib\site-packages\kombu\connection.py", line 523, in _ensured
    return fun(*args, **kwargs)
  File "C:\Users\Dmitr\PycharmProjects\project_dir\Lena\lib\site-packages\kombu\messaging.py", line 186, in _publish
    channel = self.channel
  File "C:\Users\Dmitr\PycharmProjects\project_dir\Lena\lib\site-packages\kombu\messaging.py", line 209, in _get_channel
    channel = self._channel = channel()
  File "C:\Users\Dmitr\PycharmProjects\project_dir\Lena\lib\site-packages\kombu\utils\functional.py", line 32, in __call__
    value = self.__value__ = self.__contract__()
  File "C:\Users\Dmitr\PycharmProjects\project_dir\Lena\lib\site-packages\kombu\messaging.py", line 225, in <lambda>
    channel = ChannelPromise(lambda: connection.default_channel)
  File "C:\Users\Dmitr\PycharmProjects\project_dir\Lena\lib\site-packages\kombu\connection.py", line 895, in default_channel
    self._ensure_connection(**conn_opts)
  File "C:\Users\Dmitr\PycharmProjects\project_dir\Lena\lib\site-packages\kombu\connection.py", line 433, in _ensure_connection
    return retry_over_time(
  File "C:\Users\Dmitr\AppData\Local\Programs\Python\Python39\lib\contextlib.py", line 135, in __exit__
    self.gen.throw(type, value, traceback)
  File "C:\Users\Dmitr\PycharmProjects\project_dir\Lena\lib\site-packages\kombu\connection.py", line 450, in _reraise_as_library_errors
    raise ConnectionError(str(exc)) from exc
kombu.exceptions.OperationalError: Error while reading from redis-14545.c266.us-east-1-3.ec2.cloud.redislabs.com:14545 : (10054, 'Удаленный хост принудительно разорвал существующее подключение', None, 10054, None)
2023-03-29 21:44:55,995 ERROR "POST /news/news/43/edit/ HTTP/1.1" 500 350453 C:\Users\Dmitr\PycharmProjects\project_dir\Lena\lib\site-packages\django\core\servers\basehttp.py None
